<sdf version='1.6'>
  <model name='front_actuator'>
    <link name='fixed_part_link'>
      <pose>0 0 0 0 0 0</pose>
      <inertial>
        <pose>0 0 0 0 0 0</pose>
        <mass>0.151</mass>
        <inertia>
          <ixx>0.004</ixx>
          <ixy>0</ixy>
          <ixz>0</ixz>
          <iyy>0.004</iyy>
          <iyz>0</iyz>
          <izz>0</izz>
        </inertia>
      </inertial>
      <collision name='front_actuator_collision'>
        <pose>0 0 0 0 0 0</pose>
        <geometry>
          <mesh>
            <scale>1 1 1</scale>
            <uri>model://meshes/Assembly_Linear-Actuator-Fixed-Parts_convex-hull.dae</uri>
          </mesh>
        </geometry>
        <surface>
          <contact>
            <ode>
              <min_depth>0.001</min_depth>
              <max_vel>0</max_vel>
            </ode>
          </contact>
          <friction>
            <ode/>
          </friction>
        </surface>
      </collision>
      <visual name='front_actuator_visual'>
        <pose>0 0 0 0 0 0</pose>
        <geometry>
          <mesh>
            <scale>1 1 1</scale>
            <uri>model://meshes/Assembly_Linear-Actuator-Fixed-Parts.obj</uri>
          </mesh>
        </geometry>
      </visual>
      <gravity>1</gravity>
      <velocity_decay/>
    </link>

    <link name='moving_block_link'>
      <pose>0 0.039 0.155 0 -1.57 3.14</pose>
      <inertial>
        <pose>0 0 0 0 0 0</pose>
        <mass>0.001</mass>
        <inertia>
          <ixx>0</ixx>
          <ixy>0</ixy>
          <ixz>0</ixz>
          <iyy>0</iyy>
          <iyz>0</iyz>
          <izz>0</izz>
        </inertia>
      </inertial>
      <collision name='moving_block_collision'>
        <pose>0 0 0 0 0 0</pose>
        <geometry>
          <mesh>
            <scale>1 1 1</scale>
            <uri>model://meshes/Assembly_Moving-Block_convex-hull.obj</uri>
          </mesh>
        </geometry>
        <surface>
          <contact>
            <ode>
              <min_depth>0.001</min_depth>
              <max_vel>0</max_vel>
            </ode>
          </contact>
          <friction>
            <ode/>
          </friction>
        </surface>
      </collision>
      <visual name='moving_block_visual'>
        <pose>0 0 0 0 0 0</pose>
        <geometry>
          <mesh>
            <scale>1 1 1</scale>
            <uri>model://meshes/Assembly_Moving-Block.obj</uri>
          </mesh>
        </geometry>
      </visual>
      <gravity>1</gravity>
      <velocity_decay/>
    </link>

    <joint name="front_actuator_joint" type="prismatic">      <!-- change type to fixed if neeeded -->
      <parent>fixed_part_link</parent>
      <child>moving_block_link</child>
      <axis>
        <xyz>1 0 0</xyz>
      </axis>
      <limit>
        <lower>0.155</lower>
        <upper>0.465</upper>
      </limit>
    </joint>

  </model>
</sdf>